[2024-10-23T00:50:52.554+0000] {local_task_job_runner.py:123} INFO - ::group::Pre task execution logs
[2024-10-23T00:50:52.575+0000] {taskinstance.py:2612} INFO - Dependencies all met for dep_context=non-requeueable deps ti=<TaskInstance: procesar_ocr_anthropic.procesar_ocr manual__2024-10-23T00:50:51.321037+00:00 [queued]>
[2024-10-23T00:50:52.583+0000] {taskinstance.py:2612} INFO - Dependencies all met for dep_context=requeueable deps ti=<TaskInstance: procesar_ocr_anthropic.procesar_ocr manual__2024-10-23T00:50:51.321037+00:00 [queued]>
[2024-10-23T00:50:52.583+0000] {taskinstance.py:2865} INFO - Starting attempt 1 of 2
[2024-10-23T00:50:52.594+0000] {taskinstance.py:2888} INFO - Executing <Task(PythonOperator): procesar_ocr> on 2024-10-23 00:50:51.321037+00:00
[2024-10-23T00:50:52.600+0000] {standard_task_runner.py:72} INFO - Started process 8827 to run task
[2024-10-23T00:50:52.604+0000] {standard_task_runner.py:104} INFO - Running: ['airflow', 'tasks', 'run', 'procesar_ocr_anthropic', 'procesar_ocr', 'manual__2024-10-23T00:50:51.321037+00:00', '--job-id', '5', '--raw', '--subdir', 'DAGS_FOLDER/anthropic_dag.py', '--cfg-path', '/tmp/tmpp56i6o3c']
[2024-10-23T00:50:52.605+0000] {standard_task_runner.py:105} INFO - Job 5: Subtask procesar_ocr
[2024-10-23T00:50:52.678+0000] {task_command.py:467} INFO - Running <TaskInstance: procesar_ocr_anthropic.procesar_ocr manual__2024-10-23T00:50:51.321037+00:00 [running]> on host ip-172-31-93-26.ec2.internal
[2024-10-23T00:50:52.778+0000] {taskinstance.py:3131} INFO - Exporting env vars: AIRFLOW_CTX_DAG_OWNER='airflow' AIRFLOW_CTX_DAG_ID='procesar_ocr_anthropic' AIRFLOW_CTX_TASK_ID='procesar_ocr' AIRFLOW_CTX_EXECUTION_DATE='2024-10-23T00:50:51.321037+00:00' AIRFLOW_CTX_TRY_NUMBER='1' AIRFLOW_CTX_DAG_RUN_ID='manual__2024-10-23T00:50:51.321037+00:00'
[2024-10-23T00:50:52.779+0000] {taskinstance.py:731} INFO - ::endgroup::
[2024-10-23T00:50:52.791+0000] {logging_mixin.py:190} INFO - Procesando archivo: /home/ubuntu/adjuntos/ad083001167002724418620240601095511930/ocr.txt
[2024-10-23T00:50:52.792+0000] {taskinstance.py:3310} ERROR - Task failed with exception
Traceback (most recent call last):
  File "/home/ubuntu/.local/lib/python3.10/site-packages/airflow/models/taskinstance.py", line 767, in _execute_task
    result = _execute_callable(context=context, **execute_callable_kwargs)
  File "/home/ubuntu/.local/lib/python3.10/site-packages/airflow/models/taskinstance.py", line 733, in _execute_callable
    return ExecutionCallableRunner(
  File "/home/ubuntu/.local/lib/python3.10/site-packages/airflow/utils/operator_helpers.py", line 252, in run
    return self.func(*args, **kwargs)
  File "/home/ubuntu/.local/lib/python3.10/site-packages/airflow/models/baseoperator.py", line 406, in wrapper
    return func(self, *args, **kwargs)
  File "/home/ubuntu/.local/lib/python3.10/site-packages/airflow/operators/python.py", line 238, in execute
    return_value = self.execute_callable()
  File "/home/ubuntu/.local/lib/python3.10/site-packages/airflow/operators/python.py", line 256, in execute_callable
    return runner.run(*self.op_args, **self.op_kwargs)
  File "/home/ubuntu/.local/lib/python3.10/site-packages/airflow/utils/operator_helpers.py", line 252, in run
    return self.func(*args, **kwargs)
  File "/home/ubuntu/airflow/dags/anthropic_dag.py", line 60, in procesar_todos_los_ocr
    respuesta = procesar_ocr_txt(ocr_txt_path)
  File "/home/ubuntu/airflow/dags/anthropic_dag.py", line 24, in procesar_ocr_txt
    pregunta = cargar_pregunta()
  File "/home/ubuntu/airflow/dags/anthropic_dag.py", line 18, in cargar_pregunta
    with open("/home/ubuntu/pregunta.txt", "r", encoding="utf-8") as file:
FileNotFoundError: [Errno 2] No such file or directory: '/home/ubuntu/pregunta.txt'
[2024-10-23T00:50:52.817+0000] {taskinstance.py:1225} INFO - Marking task as UP_FOR_RETRY. dag_id=procesar_ocr_anthropic, task_id=procesar_ocr, run_id=manual__2024-10-23T00:50:51.321037+00:00, execution_date=20241023T005051, start_date=20241023T005052, end_date=20241023T005052
[2024-10-23T00:50:52.832+0000] {taskinstance.py:340} INFO - ::group::Post task execution logs
[2024-10-23T00:50:52.832+0000] {standard_task_runner.py:124} ERROR - Failed to execute job 5 for task procesar_ocr ([Errno 2] No such file or directory: '/home/ubuntu/pregunta.txt'; 8827)
Traceback (most recent call last):
  File "/home/ubuntu/.local/lib/python3.10/site-packages/airflow/task/task_runner/standard_task_runner.py", line 117, in _start_by_fork
    ret = args.func(args, dag=self.dag)
  File "/home/ubuntu/.local/lib/python3.10/site-packages/airflow/cli/cli_config.py", line 49, in command
    return func(*args, **kwargs)
  File "/home/ubuntu/.local/lib/python3.10/site-packages/airflow/utils/cli.py", line 115, in wrapper
    return f(*args, **kwargs)
  File "/home/ubuntu/.local/lib/python3.10/site-packages/airflow/cli/commands/task_command.py", line 483, in task_run
    task_return_code = _run_task_by_selected_method(args, _dag, ti)
  File "/home/ubuntu/.local/lib/python3.10/site-packages/airflow/cli/commands/task_command.py", line 256, in _run_task_by_selected_method
    return _run_raw_task(args, ti)
  File "/home/ubuntu/.local/lib/python3.10/site-packages/airflow/cli/commands/task_command.py", line 341, in _run_raw_task
    return ti._run_raw_task(
  File "/home/ubuntu/.local/lib/python3.10/site-packages/airflow/utils/session.py", line 97, in wrapper
    return func(*args, session=session, **kwargs)
  File "/home/ubuntu/.local/lib/python3.10/site-packages/airflow/models/taskinstance.py", line 3004, in _run_raw_task
    return _run_raw_task(
  File "/home/ubuntu/.local/lib/python3.10/site-packages/airflow/models/taskinstance.py", line 273, in _run_raw_task
    TaskInstance._execute_task_with_callbacks(
  File "/home/ubuntu/.local/lib/python3.10/site-packages/airflow/models/taskinstance.py", line 3158, in _execute_task_with_callbacks
    result = self._execute_task(context, task_orig)
  File "/home/ubuntu/.local/lib/python3.10/site-packages/airflow/models/taskinstance.py", line 3182, in _execute_task
    return _execute_task(self, context, task_orig)
  File "/home/ubuntu/.local/lib/python3.10/site-packages/airflow/models/taskinstance.py", line 767, in _execute_task
    result = _execute_callable(context=context, **execute_callable_kwargs)
  File "/home/ubuntu/.local/lib/python3.10/site-packages/airflow/models/taskinstance.py", line 733, in _execute_callable
    return ExecutionCallableRunner(
  File "/home/ubuntu/.local/lib/python3.10/site-packages/airflow/utils/operator_helpers.py", line 252, in run
    return self.func(*args, **kwargs)
  File "/home/ubuntu/.local/lib/python3.10/site-packages/airflow/models/baseoperator.py", line 406, in wrapper
    return func(self, *args, **kwargs)
  File "/home/ubuntu/.local/lib/python3.10/site-packages/airflow/operators/python.py", line 238, in execute
    return_value = self.execute_callable()
  File "/home/ubuntu/.local/lib/python3.10/site-packages/airflow/operators/python.py", line 256, in execute_callable
    return runner.run(*self.op_args, **self.op_kwargs)
  File "/home/ubuntu/.local/lib/python3.10/site-packages/airflow/utils/operator_helpers.py", line 252, in run
    return self.func(*args, **kwargs)
  File "/home/ubuntu/airflow/dags/anthropic_dag.py", line 60, in procesar_todos_los_ocr
    respuesta = procesar_ocr_txt(ocr_txt_path)
  File "/home/ubuntu/airflow/dags/anthropic_dag.py", line 24, in procesar_ocr_txt
    pregunta = cargar_pregunta()
  File "/home/ubuntu/airflow/dags/anthropic_dag.py", line 18, in cargar_pregunta
    with open("/home/ubuntu/pregunta.txt", "r", encoding="utf-8") as file:
FileNotFoundError: [Errno 2] No such file or directory: '/home/ubuntu/pregunta.txt'
[2024-10-23T00:50:52.860+0000] {local_task_job_runner.py:266} INFO - Task exited with return code 1
[2024-10-23T00:50:52.886+0000] {taskinstance.py:3900} INFO - 0 downstream tasks scheduled from follow-on schedule check
[2024-10-23T00:50:52.888+0000] {local_task_job_runner.py:245} INFO - ::endgroup::
